Workbook

Sheet Instrucciones
B2: Simulador PMR – CR-L1137 (versión reconstruida, editable)
B4: Por qué existe esta versión
B5: El simulador oficial (PMR_SIMULATOR CR-L1137) calcula SI = 1,8 (Problema) porque la tabla dinámica 'Pivot EOP Output for milestone' está vacía. Esa tabla alimenta 'Data milestones a output', de donde salen el EV y EV(a) de los productos por hitos (P.1.7 Delegaciones y P.2.7 CCP). Al no encontrarlos, el EV de esos productos queda en blanco (EV total US$3,2mn en lugar de US$41,3mn) y SPI(a)/CPI(a) caen a ≈0,04. Como el archivo está protegido, no es posible refrescar la tabla dinámica.
B6: Esta versión reproduce la metodología del simulador oficial con fórmulas abiertas y, con los datos del PMR de junio 2026, devuelve SI = 2,70 (Satisfactorio), igual que el reporte PMR (ver hoja Resultados, fila 'Control vs. PMR').
B8: Cómo usarlo
B9: 1. Hoja 'Escenarios': edite las celdas amarillas. Hay tres escenarios (E1, E2, E3) además del caso Base (PMR jun-2026). Para cada escenario puede indicar: fecha de corte (define los meses desde elegibilidad y el benchmark de desembolsos), desembolso acumulado, y por producto: avance físico adicional en el año, y gasto adicional (US$) en el año. Para los productos por hitos, registre el avance adicional por hito. Las metas del año (P y P(a)) no se pueden modificar: se bloquean en marzo de cada año (las de 2026 en marzo 2026). Solo se mueven el desembolso, el cumplimiento físico y la ejecución financiera.
B10: 2. Hoja 'Resultados': muestra lado a lado los indicadores, su semáforo, el indicador sintético (SI) y la clasificación para Base, E1, E2 y E3.
B11: 3. Hojas 'Fisico', 'Financiero' e 'Hitos': datos base tomados del simulador oficial y del PMR (I semestre 2026). Pueden actualizarse en el próximo ciclo (celdas amarillas).
B12: 4. Hoja 'Parametros': año evaluado, datos de la operación, modalidad (GOM → Caso 1 de ponderación) y ponderaciones del SI.
B13: Los escenarios E1–E3 vienen precargados como ejemplo (supuestos ilustrativos, no datos del ejecutor); sobrescríbalos.
B15: Metodología replicada (simulador oficial PMR)
B16: • PV = P financiero acumulado hasta el año evaluado. PV(a) = A financiero acumulado de años anteriores + P(a) financiero del año evaluado. AC = A financiero acumulado hasta el año evaluado.
... B25: • No replica ajustes manuales que SPD pueda hacer en Convergencia ni cambios a la Matriz de Resultados posteriores al PMR.

Sheet Resultados
A1: Resultados por escenario – CR-L1137
A2: Calificación PMR simulada. Cambie los supuestos en la hoja 'Escenarios'.
A4: Concepto | B4: Base | C4: E1 | D4: E2 | E4: E3
A5: Escenario | B5: =Escenarios!C5 -> Base PMR jun-2026 | C5: =Escenarios!D5 -> Cierre 2026 sin cambios | D5: =Escenarios!E5 -> Entregas DP jul-ago 2026 | E5: =Escenarios!F5 -> Gasto sin avance físico
A6: Fecha de corte | B6: =Escenarios!C7 -> 46203 | C6: =Escenarios!D7 -> 46387 | D6: =Escenarios!E7 -> 46387 | E6: =Escenarios!F7 -> 46387
A7: Meses desde 1ra elegibilidad | B7: =DATEDIF(Parametros!$C$7,B6,"m") -> 61 | C7: =DATEDIF(Parametros!$C$7,C6,"m") -> 67 | D7: =DATEDIF(Parametros!$C$7,D6,"m") -> 67 | E7: =DATEDIF(Parametros!$C$7,E6,"m") -> 67
A8: Desembolso acumulado (%) | B8: =Escenarios!C8/Parametros!$C$5 -> 0.819 | C8: =Escenarios!D8/Parametros!$C$5 -> 0.819 | D8: =Escenarios!E8/Parametros!$C$5 -> 0.819 | E8: =Escenarios!F8/Parametros!$C$5 -> 0.819
A9: Umbral satisfactorio desembolsos (≥) | B9: =IF(Escenarios!C9<>"",Escenarios!C9,INDEX(Curva_CR!$B$4:$B$204,MATCH(B7,Curva_CR!$A$4:$A$204,0))) -> 0.51 | C9: =IF(Escenarios!D9<>"",Escenarios!D9,INDEX(Curva_CR!$B$4:$B$204,MATCH(C7,Curva_CR!$A$4:$A$204,0))) -> 0.61054 | D9: =IF(Escenarios!E9<>"",Escenarios!E9,INDEX(Curva_CR!$B$4:$B$204,MATCH(D7,Curva_CR!$A$4:$A$204,0))) -> 0.61054 | E9: =IF(Escenarios!F9<>"",Escenarios!F9,INDEX(Curva_CR!$B$4:$B$204,MATCH(E7,Curva_CR!$A$4:$A$204,0))) -> 0.61054
A10: Umbral problema desembolsos (<) | B10: =IF(Escenarios!C10<>"",Escenarios!C10,INDEX(Curva_CR!$C$4:$C$204,MATCH(B7,Curva_CR!$A$4:$A$204,0))) -> 0.44 | C10: =IF(Escenarios!D10<>"",Escenarios!D10,INDEX(Curva_CR!$C$4:$C$204,MATCH(C7,Curva_CR!$A$4:$A$204,0))) -> 0.53796 | D10: =IF(Escenarios!E10<>"",Escenarios!E10,INDEX(Curva_CR!$C$4:$C$204,MATCH(D7,Curva_CR!$A$4:$A$204,0))) -> 0.53796 | E10: =IF(Escenarios!F10<>"",Escenarios!F10,INDEX(Curva_CR!$C$4:$C$204,MATCH(E7,Curva_CR!$A$4:$A$204,0))) -> 0.53796
A11: Semáforo desembolsos | B11: =IF(B8>=B9,"Satisfactorio",IF(B8>=B10,"Alerta","Problema")) -> Satisfactorio | C11: =IF(C8>=C9,"Satisfactorio",IF(C8>=C10,"Alerta","Problema")) -> Satisfactorio | D11: =IF(D8>=D9,"Satisfactorio",IF(D8>=D10,"Alerta","Problema")) -> Satisfactorio | E11: =IF(E8>=E9,"Satisfactorio",IF(E8>=E10,"Alerta","Problema")) -> Satisfactorio
A12: PV (US$) | B12: =Calculo!D20 -> 95500000 | C12: =Calculo!D52 -> 95500000 | D12: =Calculo!D84 -> 95500000 | E12: =Calculo!D116 -> 95500000
A13: PV(a) (US$) | B13: =Calculo!E20 -> 84265872 | C13: =Calculo!E52 -> 84265872 | D13: =Calculo!E84 -> 84265872 | E13: =Calculo!E116 -> 84265872
A14: AC (US$) | B14: =Calculo!F20 -> 73541092 | C14: =Calculo!F52 -> 73541092 | D14: =Calculo!F84 -> 77515584 | E14: =Calculo!F116 -> 81541092
A15: EV (US$) | B15: =Calculo!L20 -> 41258690 | C15: =Calculo!L52 -> 41258690 | D15: =Calculo!L84 -> 45715364 | E15: =Calculo!L116 -> 41258690
A16: EV(a) (US$) | B16: =Calculo!M20 -> 61941159 | C16: =Calculo!M52 -> 61941159 | D16: =Calculo!M84 -> 71116664 | E16: =Calculo!M116 -> 61941159
A17: SPI = EV/PV | B17: =IF(AND(B12=0,B14=0),1,IF(B14=0,0,B15/B12)) -> 0.43202817 | C17: =IF(AND(C12=0,C14=0),1,IF(C14=0,0,C15/C12)) -> 0.43202817 | D17: =IF(AND(D12=0,D14=0),1,IF(D14=0,0,D15/D12)) -> 0.47869491 | E17: =IF(AND(E12=0,E14=0),1,IF(E14=0,0,E15/E12)) -> 0.43202817
A18: Semáforo SPI | B18: =IF(AND(B17>=Parametros!$C$29,B17<=Parametros!$C$31),"Satisfactorio",IF(AND(B17>=Parametros!$C$30,B17<Parametros!$C$29),"Alerta",IF(B17<Parametros!$C$30,"Problema","Outlier"))) -> Alerta | C18: =IF(AND(C17>=Parametros!$C$29,C17<=Parametros!$C$31),"Satisfactorio",IF(AND(C17>=Parametros!$C$30,C17<Parametros!$C$29),"Alerta",IF(C17<Parametros!$C$30,"Problema","Outlier"))) -> Alerta | D18: =IF(AND(D17>=Parametros!$C$29,D17<=Parametros!$C$31),"Satisfactorio",IF(AND(D17>=Parametros!$C$30,D17<Parametros!$C$29),"Alerta",IF(D17<Parametros!$C$30,"Problema","Outlier"))) -> Alerta | E18: =IF(AND(E17>=Parametros!$C$29,E17<=Parametros!$C$31),"Satisfactorio",IF(AND(E17>=Parametros!$C$30,E17<Parametros!$C$29),"Alerta",IF(E17<Parametros!$C$30,"Problema","Outlier"))) -> Alerta
A19: SPI(a) = EV(a)/PV(a) | B19: =IF(AND(B13=0,B14=0),1,IF(B14=0,0,B16/B13)) -> 0.73506815 | C19: =IF(AND(C13=0,C14=0),1,IF(C14=0,0,C16/C13)) -> 0.73506815 | D19: =IF(AND(D13=0,D14=0),1,IF(D14=0,0,D16/D13)) -> 0.84395572 | E19: =IF(AND(E13=0,E14=0),1,IF(E14=0,0,E16/E13)) -> 0.73506815
A20: Semáforo SPI(a) | B20: =IF(AND(B19>=Parametros!$C$29,B19<=Parametros!$C$31),"Satisfactorio",IF(AND(B19>=Parametros!$C$30,B19<Parametros!$C$29),"Alerta",IF(B19<Parametros!$C$30,"Problema","Outlier"))) -> Alerta | C20: =IF(AND(C19>=Parametros!$C$29,C19<=Parametros!$C$31),"Satisfactorio",IF(AND(C19>=Parametros!$C$30,C19<Parametros!$C$29),"Alerta",IF(C19<Parametros!$C$30,"Problema","Outlier"))) -> Alerta | D20: =IF(AND(D19>=Parametros!$C$29,D19<=Parametros!$C$31),"Satisfactorio",IF(AND(D19>=Parametros!$C$30,D19<Parametros!$C$29),"Alerta",IF(D19<Parametros!$C$30,"Problema","Outlier"))) -> Satisfactorio | E20: =IF(AND(E19>=Parametros!$C$29,E19<=Parametros!$C$31),"Satisfactorio",IF(AND(E19>=Parametros!$C$30,E19<Parametros!$C$29),"Alerta",IF(E19<Parametros!$C$30,"Problema","Outlier"))) -> Alerta
A21: CPI = EV/AC | B21: =IF(B14=0,IF(B12=0,1,0),B15/B14) -> 0.56102907 | C21: =IF(C14=0,IF(C12=0,1,0),C15/C14) -> 0.56102907 | D21: =IF(D14=0,IF(D12=0,1,0),D15/D14) -> 0.58975708 | E21: =IF(E14=0,IF(E12=0,1,0),E15/E14) -> 0.50598648
A22: Semáforo CPI | B22: =IF(AND(B21>=Parametros!$C$29,B21<=Parametros!$C$31),"Satisfactorio",IF(AND(B21>=Parametros!$C$30,B21<Parametros!$C$29),"Alerta",IF(B21<Parametros!$C$30,"Problema","Outlier"))) -> Alerta | C22: =IF(AND(C21>=Parametros!$C$29,C21<=Parametros!$C$31),"Satisfactorio",IF(AND(C21>=Parametros!$C$30,C21<Parametros!$C$29),"Alerta",IF(C21<Parametros!$C$30,"Problema","Outlier"))) -> Alerta | D22: =IF(AND(D21>=Parametros!$C$29,D21<=Parametros!$C$31),"Satisfactorio",IF(AND(D21>=Parametros!$C$30,D21<Parametros!$C$29),"Alerta",IF(D21<Parametros!$C$30,"Problema","Outlier"))) -> Alerta | E22: =IF(AND(E21>=Parametros!$C$29,E21<=Parametros!$C$31),"Satisfactorio",IF(AND(E21>=Parametros!$C$30,E21<Parametros!$C$29),"Alerta",IF(E21<Parametros!$C$30,"Problema","Outlier"))) -> Alerta
A23: CPI(a) = EV(a)/AC | B23: =IF(B14=0,IF(B13=0,1,0),B16/B14) -> 0.84226597 | C23: =IF(C14=0,IF(C13=0,1,0),C16/C14) -> 0.84226597 | D23: =IF(D14=0,IF(D13=0,1,0),D16/D14) -> 0.91744989 | E23: =IF(E14=0,IF(E13=0,1,0),E16/E14) -> 0.75963122
A24: Semáforo CPI(a) | B24: =IF(AND(B23>=Parametros!$C$29,B23<=Parametros!$C$31),"Satisfactorio",IF(AND(B23>=Parametros!$C$30,B23<Parametros!$C$29),"Alerta",IF(B23<Parametros!$C$30,"Problema","Outlier"))) -> Satisfactorio | C24: =IF(AND(C23>=Parametros!$C$29,C23<=Parametros!$C$31),"Satisfactorio",IF(AND(C23>=Parametros!$C$30,C23<Parametros!$C$29),"Alerta",IF(C23<Parametros!$C$30,"Problema","Outlier"))) -> Satisfactorio | D24: =IF(AND(D23>=Parametros!$C$29,D23<=Parametros!$C$31),"Satisfactorio",IF(AND(D23>=Parametros!$C$30,D23<Parametros!$C$29),"Alerta",IF(D23<Parametros!$C$30,"Problema","Outlier"))) -> Satisfactorio | E24: =IF(AND(E23>=Parametros!$C$29,E23<=Parametros!$C$31),"Satisfactorio",IF(AND(E23>=Parametros!$C$30,E23<Parametros!$C$29),"Alerta",IF(E23<Parametros!$C$30,"Problema","Outlier"))) -> Alerta
A25: Semáforo meses desde 95% (solo etapa 3) | B25: =IF(Parametros!$C$9="Etapa 3",IF(Parametros!$C$10<=Parametros!$C$11,"Satisfactorio",IF(Parametros!$C$10<=Parametros!$C$12,"Alerta","Problema")),"N/A") -> N/A | C25: =IF(Parametros!$C$9="Etapa 3",IF(Parametros!$C$10<=Parametros!$C$11,"Satisfactorio",IF(Parametros!$C$10<=Parametros!$C$12,"Alerta","Problema")),"N/A") -> N/A | D25: =IF(Parametros!$C$9="Etapa 3",IF(Parametros!$C$10<=Parametros!$C$11,"Satisfactorio",IF(Parametros!$C$10<=Parametros!$C$12,"Alerta","Problema")),"N/A") -> N/A | E25: =IF(Parametros!$C$9="Etapa 3",IF(Parametros!$C$10<=Parametros!$C$11,"Satisfactorio",IF(Parametros!$C$10<=Parametros!$C$12,"Alerta","Problema")),"N/A") -> N/A
A26: INDICADOR SINTÉTICO (SI) | B26: =ROUND(IF(Parametros!$C$9="Etapa 3",(INDEX(Parametros!$C$17:$D$17,1,Parametros!$C$24)*IF(B11="Satisfactorio",3,IF(B11="Alerta",2,1))+INDEX(Parametros!$C$18:$D$18,1,Parametros!$C$24)*IF(B18="Satisfactorio",3,IF(B18="Alerta",2,1))+INDEX(Parametros!$C$19:$D$19,1,Parametros!$C$24)*IF(B20="Satisfactorio",3,IF(B20="Alerta",2,1))+INDEX(Parametros!$C$20:$D$20,1,Parametros!$C$24)*IF(B22="Satisfactorio",3,IF(B22="Alerta",2,1))+INDEX(Parametros!$C$21:$D$21,1,Parametros!$C$24)*IF(B24="Satisfactorio",3,IF(B24="Alerta",2,1)))*0.8+INDEX(Parametros!$C$22:$D$22,1,Parametros!$C$24)*IF(B25="Satisfactorio",3,IF(B25="Alerta",2,1)),INDEX(Parametros!$C$17:$D$17,1,Parametros!$C$24)*IF(B11="Satisfactorio",3,IF(B11="Alerta",2,1))+INDEX(Parametros!$C$18:$D$18,1,Parametros!$C$24)*IF(B18="Satisfactorio",3,IF(B18="Alerta",2,1))+INDEX(Parametros!$C$19:$D$19,1,Parametros!$C$24)*IF(B20="Satisfactorio",3,IF(B20="Alerta",2,1))+INDEX(Parametros!$C$20:$D$20,1,Parametros!$C$24)*IF(B22="Satisfactorio",3,IF(B22="Alerta",2,1))+INDEX(Parametros!$C$21:$D$21,1,Parametros!$C$24)*IF(B24="Satisfactorio",3,IF(B24="Alerta",2,1))),2) -> 2.7 | C26: =ROUND(IF(Parametros!$C$9="Etapa 3",(INDEX(Parametros!$C$17:$D$17,1,Parametros!$C$24)*IF(C11="Satisfactorio",3,IF(C11="Alerta",2,1))+INDEX(Parametros!$C$18:$D$18,1,Parametros!$C$24)*IF(C18="Satisfactorio",3,IF(C18="Alerta",2,1))+INDEX(Parametros!$C$19:$D$19,1,Parametros!$C$24)*IF(C20="Satisfactorio",3,IF(C20="Alerta",2,1))+INDEX(Parametros!$C$20:$D$20,1,Parametros!$C$24)*IF(C22="Satisfactorio",3,IF(C22="Alerta",2,1))+INDEX(Parametros!$C$21:$D$21,1,Parametros!$C$24)*IF(C24="Satisfactorio",3,IF(C24="Alerta",2,1)))*0.8+INDEX(Parametros!$C$22:$D$22,1,Parametros!$C$24)*IF(C25="Satisfactorio",3,IF(C25="Alerta",2,1)),INDEX(Parametros!$C$17:$D$17,1,Parametros!$C$24)*IF(C11="Satisfactorio",3,IF(C11="Alerta",2,1))+INDEX(Parametros!$C$18:$D$18,1,Parametros!$C$24)*IF(C18="Satisfactorio",3,IF(C18="Alerta",2,1))+INDEX(Parametros!$C$19:$D$19,1,Parametros!$C$24)*IF(C20="Satisfactorio",3,IF(C20="Alerta",2,1))+INDEX(Parametros!$C$20:$D$20,1,Parametros!$C$24)*IF(C22="Satisfactorio",3,IF(C22="Alerta",2,1))+INDEX(Parametros!$C$21:$D$21,1,Parametros!$C$24)*IF(C24="Satisfactorio",3,IF(C24="Alerta",2,1))),2) -> 2.7 | D26: =ROUND(IF(Parametros!$C$9="Etapa 3",(INDEX(Parametros!$C$17:$D$17,1,Parametros!$C$24)*IF(D11="Satisfactorio",3,IF(D11="Alerta",2,1))+INDEX(Parametros!$C$18:$D$18,1,Parametros!$C$24)*IF(D18="Satisfactorio",3,IF(D18="Alerta",2,1))+INDEX(Parametros!$C$19:$D$19,1,Parametros!$C$24)*IF(D20="Satisfactorio",3,IF(D20="Alerta",2,1))+INDEX(Parametros!$C$20:$D$20,1,Parametros!$C$24)*IF(D22="Satisfactorio",3,IF(D22="Alerta",2,1))+INDEX(Parametros!$C$21:$D$21,1,Parametros!$C$24)*IF(D24="Satisfactorio",3,IF(D24="Alerta",2,1)))*0.8+INDEX(Parametros!$C$22:$D$22,1,Parametros!$C$24)*IF(D25="Satisfactorio",3,IF(D25="Alerta",2,1)),INDEX(Parametros!$C$17:$D$17,1,Parametros!$C$24)*IF(D11="Satisfactorio",3,IF(D11="Alerta",2,1))+INDEX(Parametros!$C$18:$D$18,1,Parametros!$C$24)*IF(D18="Satisfactorio",3,IF(D18="Alerta",2,1))+INDEX(Parametros!$C$19:$D$19,1,Parametros!$C$24)*IF(D20="Satisfactorio",3,IF(D20="Alerta",2,1))+INDEX(Parametros!$C$20:$D$20,1,Parametros!$C$24)*IF(D22="Satisfactorio",3,IF(D22="Alerta",2,1))+INDEX(Parametros!$C$21:$D$21,1,Parametros!$C$24)*IF(D24="Satisfactorio",3,IF(D24="Alerta",2,1))),2) -> 3 | E26: =ROUND(IF(Parametros!$C$9="Etapa 3",(INDEX(Parametros!$C$17:$D$17,1,Parametros!$C$24)*IF(E11="Satisfactorio",3,IF(E11="Alerta",2,1))+INDEX(Parametros!$C$18:$D$18,1,Parametros!$C$24)*IF(E18="Satisfactorio",3,IF(E18="Alerta",2,1))+INDEX(Parametros!$C$19:$D$19,1,Parametros!$C$24)*IF(E20="Satisfactorio",3,IF(E20="Alerta",2,1))+INDEX(Parametros!$C$20:$D$20,1,Parametros!$C$24)*IF(E22="Satisfactorio",3,IF(E22="Alerta",2,1))+INDEX(Parametros!$C$21:$D$21,1,Parametros!$C$24)*IF(E24="Satisfactorio",3,IF(E24="Alerta",2,1)))*0.8+INDEX(Parametros!$C$22:$D$22,1,Parametros!$C$24)*IF(E25="Satisfactorio",3,IF(E25="Alerta",2,1)),INDEX(Parametros!$C$17:$D$17,1,Parametros!$C$24)*IF(E11="Satisfactorio",3,IF(E11="Alerta",2,1))+INDEX(Parametros!$C$18:$D$18,1,Parametros!$C$24)*IF(E18="Satisfactorio",3,IF(E18="Alerta",2,1))+INDEX(Parametros!$C$19:$D$19,1,Parametros!$C$24)*IF(E20="Satisfactorio",3,IF(E20="Alerta",2,1))+INDEX(Parametros!$C$20:$D$20,1,Parametros!$C$24)*IF(E22="Satisfactorio",3,IF(E22="Alerta",2,1))+INDEX(Parametros!$C$21:$D$21,1,Parametros!$C$24)*IF(E24="Satisfactorio",3,IF(E24="Alerta",2,1))),2) -> 2.4
A27: CLASIFICACIÓN | B27: =IF(B26>=Parametros!$C$27,"Satisfactorio",IF(B26>=Parametros!$C$28,"Alerta","Problema")) -> Satisfactorio | C27: =IF(C26>=Parametros!$C$27,"Satisfactorio",IF(C26>=Parametros!$C$28,"Alerta","Problema")) -> Satisfactorio | D27: =IF(D26>=Parametros!$C$27,"Satisfactorio",IF(D26>=Parametros!$C$28,"Alerta","Problema")) -> Satisfactorio | E27: =IF(E26>=Parametros!$C$27,"Satisfactorio",IF(E26>=Parametros!$C$28,"Alerta","Problema")) -> Alerta
A28: Margen: gasto adicional sin avance antes de que CPI(a) baje de 0,80 (US$) | B28: =MAX(0,B16/Parametros!$C$29-B14) -> 3885356.6 | C28: =MAX(0,C16/Parametros!$C$29-C14) -> 3885356.6 | D28: =MAX(0,D16/Parametros!$C$29-D14) -> 11380246 | E28: =MAX(0,E16/Parametros!$C$29-E14) -> 0
A29: Brecha: EV(a) adicional para SPI(a) satisfactorio (US$) | B29: =MAX(0,Parametros!$C$29*B13-B16) -> 5471538.5 | C29: =MAX(0,Parametros!$C$29*C13-C16) -> 5471538.5 | D29: =MAX(0,Parametros!$C$29*D13-D16) -> 0 | E29: =MAX(0,Parametros!$C$29*E13-E16) -> 5471538.5
A31: Control vs. PMR (jun-2026): SI 2,70 / SPI(a) 0,74 / CPI(a) 0,84 / Desembolso 0,82 | B31: =IF(AND(B26=2.7,ROUND(B19,2)=0.74,ROUND(B23,2)=0.84),"OK – reproduce el PMR","Revisar") -> OK – reproduce el PMR
A32: Simulador oficial (archivo protegido) | B32: SI 1,8 – Problema (EV de hitos no calculado)

Sheet Escenarios
A1: Escenarios – edite las celdas amarillas
A2: Base = PMR I semestre 2026 sin cambios (no editable aquí). E1–E3 vienen con supuestos de ejemplo.
B4: Parámetro del escenario | C4: Base (PMR jun-26) | D4: E1 | E4: E2 | F4: E3
B5: Nombre | C5: Base PMR jun-2026 | D5: Cierre 2026 sin cambios | E5: Entregas DP jul-ago 2026 | F5: Gasto sin avance físico
B6: Descripción | C6: Datos del PMR validado (corte 30-jun-2026) | D6: Mismos datos, evaluados con el benchmark de desembolsos al 31-dic-2026 | E6: Entrega de DP Desamparados Norte, Turrialba y Pococí (+3) y ejecución del P(a) 2026 de delegaciones (+US$3,97mn) | F6: Pagos adicionales sin avance físico: +US$3mn delegaciones y +US$5mn CCP
B7: Fecha de corte | C7: 46203 | D7: 46387 | E7: 46387 | F7: 46387
B8: Desembolso acumulado (US$) | C8: 81900000 | D8: 81900000 | E8: 81900000 | F8: 81900000
B9: Umbral desembolso satisfactorio (manual, opcional) | C9: 0.51 | G9: Base: umbrales que muestra el PMR de junio. Vacío = usar la curva (hoja Curva_CR).
B10: Umbral desembolso problema (manual, opcional) | C10: 0.44
B13: Ajustes por producto (en el año evaluado)
C14: E1 | E14: E2 | G14: E3
A15: Nro | B15: Producto | C15: A físico adicional | D15: A financiero adicional (US$) | E15: A físico adicional | F15: A financiero adicional (US$) | G15: A físico adicional | H15: A financiero adicional (US$)
A16: 1 | B16: =Fisico!B5 -> P1.1. Plataformas de datos policiales integradas e interoperables
A17: 2 | B17: =Fisico!B8 -> P1.2. Sistema de información delictual fortalecidos y en funcionamiento
A18: 3 | B18: =Fisico!B11 -> P.1.3. Departamentos de la FP capacitados en análisis criminal y monitoreo de dinámicas delictivas
A19: 4 | B19: =Fisico!B14 -> P.1.4. Estrategias policiales basadas en evidencia diseñadas e implementadas
A20: 5 | B20: =Fisico!B17 -> P.1.5. Evaluación de impacto de estrategias policiales basadas en evidencia diseñada e implementada
A21: 6 | B21: =Fisico!B20 -> P.1.6. Sistema de procesamiento de quejas ciudadanas y procesos disciplinarios, fortalecido
A22: 7 | B22: =Fisico!B23 -> P.1.7. Delegaciones diseñadas, construida, equipadas y operando bajo el enfoque de policía comunitaria | E22: 3 | F22: 3974492 | H22: 3000000
A23: 8 | B23: =Fisico!B26 -> Centro de Mando y Control Policial (CMCP) diseñado, construido, equipado y en funcionamiento
A24: 9 | B24: =Fisico!B29 -> P.2.1. Modelo de atención de los CCP actualizado, fortalecido, y en funcionamiento en los CCPs de la red
A25: 10 | B25: =Fisico!B32 -> P.2.2. Modelo de gestión de los CCP homologado, fortalecido y en funcionamiento en los CCPs de la red
A26: 11 | B26: =Fisico!B35 -> P.2.3. Municipalidades y grupos de sociedad civil capacitados y utilizando las nuevas competencias adquiridas en prevención de violencia
A27: 12 | B27: =Fisico!B38 -> P.2.4. Estrategia de comunicación social de los CCP, diseñada e implementada
A28: 13 | B28: =Fisico!B41 -> P.2.5. Sistema de información integrado de los CCP, desarrollado e implementado
A29: 14 | B29: =Fisico!B44 -> P.2.6. Evaluación de impacto de los CCP diseñada e implementada
A30: 15 | B30: =Fisico!B47 -> P.2.7. CCP diseñados, construidos, equipados y en funcionamiento | H30: 5000000
B33: Ajustes por hito (avance físico adicional en el año evaluado)
A34: Nro producto | B34: Hito | C34: E1 | D34: E2 | E34: E3
A35: =Hitos!A5 -> 7 | B35: =Hitos!B5 -> Delegaciones Policiales diseñadas
A36: =Hitos!A8 -> 7 | B36: =Hitos!B8 -> Delegaciones Policiales construidas, equipadas y operando | D36: 3
A37: =Hitos!A11 -> 15 | B37: =Hitos!B11 -> CCPs diseñados
A38: =Hitos!A14 -> 15 | B38: =Hitos!B14 -> CCPs construidos, equipados y en funcionamiento
A39: =Hitos!A17 -> 15 | B39: =Hitos!B17 -> Techados de Skate Parks Garabito y Santa Cruz construidos
B41: Nota: para un producto por hitos, el EV depende de los hitos; el 'A físico adicional' del producto solo cambia el %P informativo. Registre el avance en esta tabla.

Sheet Parametros
B2: Parámetros de la operación
B4: Operación | C4: CR-L1137 | E4: Citizen Security and Violence Prevention Program (4871/OC-CR)
B5: Monto aprobado vigente (US$) | C5: 100000000 | E5: PMR / simulador oficial
B6: Año evaluado | C6: 2026 | E6: Año de clasificación
B7: Fecha de primera elegibilidad | C7: 44328 | E7: Simulador oficial, hoja Operation Basic Data
B8: ¿Modalidad GOM? (Sí/No) | C8: Sí | E8: Sí → Caso 1 de ponderación
B9: Etapa PMR (Etapa 2 / Etapa 3) | C9: Etapa 2 | E9: Etapa 3 = después de 95% desembolsado
B10: Meses desde 95% desembolsado (solo etapa 3) | C10: 0
B11: Umbral satisfactorio T3 (meses ≤) | C11: 11.78 | E11: Simulador oficial (benchmarks 2026)
B12: Umbral problema T3 (meses >) | C12: 17.05 | E12: Simulador oficial (benchmarks 2026)
B15: Ponderaciones del indicador sintético
B16: Indicador | C16: Caso 1 (GOM) | D16: Caso 2
B17: Desembolsos | C17: 0.4 | D17: 0.1
B18: SPI | C18: 0 | D18: 0.15
B19: SPI(a) | C19: 0.3 | D19: 0.3
B20: CPI | C20: 0 | D20: 0.15
B21: CPI(a) | C21: 0.3 | D21: 0.3
B22: Meses desde 95% (T3, etapa 3) | C22: 0.2 | D22: 0.2
B24: Caso de ponderación aplicado | C24: =IF(C8="Sí",1,2) -> 1 | E24: Fuente: simulador oficial, hoja 'Actualizar benchmarks' (J12:K17)
B26: Umbrales
B27: SI satisfactorio (≥) | C27: 2.5
B28: SI alerta (≥) | C28: 2
B29: Índices: satisfactorio desde | C29: 0.8
B30: Índices: alerta desde | C30: 0.4
B31: Índices: outlier sobre | C31: 2

Sheet Fisico
A1: Datos físicos por producto – base PMR I semestre 2026 (fuente: simulador oficial)
A4: Nro | B4: Producto | C4: Unidad | D4: ¿Por hitos? | E4: Tipo | F4: 2020 | G4: 2021 | H4: 2022 | I4: 2023 | J4: 2024 | K4: 2025 | L4: 2026 | M4: 2027 | N4: EOP
A5: 1 | B5: P1.1. Plataformas de datos policiales integradas e interoperables | C5: # of agencies | D5: No | E5: P | F5: 0 | G5: 0 | H5: 0 | I5: 0 | J5: 1 | K5: 0 | L5: 0 | M5: 0 | N5: 1
A6: 1 | E6: P(a) | F6: 0 | G6: 0 | H6: 0 | I6: 0 | J6: 0 | K6: 0 | L6: 0 | M6: 1 | N6: 1
A7: 1 | E7: A | F7: 0 | G7: 0 | H7: 0 | I7: 0 | J7: 0 | K7: 0 | L7: 0 | M7: 0 | N7: 0
A8: 2 | B8: P1.2. Sistema de información delictual fortalecidos y en funcionamiento | C8: # of agencies | D8: No | E8: P | F8: 0 | G8: 0 | H8: 0 | I8: 0 | J8: 1 | K8: 0 | L8: 0 | M8: 0 | N8: 1
A9: 2 | E9: P(a) | F9: 0 | G9: 0 | H9: 0 | I9: 0 | J9: 0 | K9: 0 | L9: 0 | M9: 1 | N9: 1
A10: 2 | E10: A | F10: 0 | G10: 0 | H10: 0 | I10: 0 | J10: 0 | K10: 0 | L10: 0 | M10: 0 | N10: 0
A11: 3 | B11: P.1.3. Departamentos de la FP capacitados en análisis criminal y monitoreo de dinámicas delictivas | C11: # de departamentos | D11: No | E11: P | F11: 0 | G11: 0 | H11: 0 | I11: 0 | J11: 16 | K11: 0 | L11: 0 | M11: 0 | N11: 16
A12: 3 | E12: P(a) | F12: 0 | G12: 0 | H12: 0 | I12: 0 | J12: 0 | K12: 0 | L12: 0 | M12: 0 | N12: 29
A13: 3 | E13: A | F13: 0 | G13: 0 | H13: 0 | I13: 29 | J13: 0 | K13: 0 | L13: 0 | M13: 0 | N13: 29
A14: 4 | B14: P.1.4. Estrategias policiales basadas en evidencia diseñadas e implementadas | C14: # of agencies | D14: No | E14: P | F14: 0 | G14: 0 | H14: 0 | I14: 0 | J14: 0 | K14: 1 | L14: 0 | M14: 0 | N14: 1
A15: 4 | E15: P(a) | F15: 0 | G15: 0 | H15: 0 | I15: 0 | J15: 0 | K15: 1 | L15: 1 | M15: 0 | N15: 1
A16: 4 | E16: A | F16: 0 | G16: 0 | H16: 0 | I16: 0 | J16: 0 | K16: 0 | L16: 0 | M16: 0 | N16: 0
A17: 5 | B17: P.1.5. Evaluación de impacto de estrategias policiales basadas en evidencia diseñada e implementada | C17: Evaluación | D17: No | E17: P | F17: 0 | G17: 0 | H17: 0 | I17: 0 | J17: 0 | K17: 1 | L17: 0 | M17: 0 | N17: 1
A18: 5 | E18: P(a) | F18: 0 | G18: 0 | H18: 0 | I18: 0 | J18: 0 | K18: 1 | L18: 1 | M18: 0 | N18: 1
A19: 5 | E19: A | F19: 0 | G19: 0 | H19: 0 | I19: 0 | J19: 0 | K19: 0 | L19: 0 | M19: 0 | N19: 0
A20: 6 | B20: P.1.6. Sistema de procesamiento de quejas ciudadanas y procesos disciplinarios, fortalecido | C20: # of agencies | D20: No | E20: P | F20: 0 | G20: 0 | H20: 0 | I20: 0 | J20: 1 | K20: 0 | L20: 0 | M20: 0 | N20: 1
A21: 6 | E21: P(a) | F21: 0 | G21: 0 | H21: 0 | I21: 0 | J21: 0 | K21: 1 | L21: 1 | M21: 0 | N21: 1
A22: 6 | E22: A | F22: 0 | G22: 0 | H22: 0 | I22: 0 | J22: 0 | K22: 0 | L22: 0 | M22: 0 | N22: 0
A23: 7 | B23: P.1.7. Delegaciones diseñadas, construida, equipadas y operando bajo el enfoque de policía comunitaria | C23: Subnational governments (#) | D23: Sí | E23: P | F23: 0 | G23: 0 | H23: 0 | I23: 4 | J23: 7 | K23: 10 | L23: 14 | M23: 0 | N23: 35
A24: 7 | E24: P(a) | F24: 0 | G24: 0 | H24: 0 | I24: 2 | J24: 6 | K24: 2 | L24: 4 | M24: 6 | N24: 17
A25: 7 | E25: A | F25: 0 | G25: 0 | H25: 0 | I25: 1 | J25: 5 | K25: 1 | L25: 8 | M25: 0 | N25: 12
A26: 8 | B26: Centro de Mando y Control Policial (CMCP) diseñado, construido, equipado y en funcionamiento | C26: Número | D26: No | E26: P | F26: 0 | G26: 0 | H26: 0 | I26: 0 | J26: 0 | K26: 0 | L26: 0 | M26: 0 | N26: 0
A27: 8 | E27: P(a) | F27: 0 | G27: 0 | H27: 0 | I27: 0 | J27: 0 | K27: 0 | L27: 0 | M27: 1 | N27: 1
A28: 8 | E28: A | F28: 0 | G28: 0 | H28: 0 | I28: 0 | J28: 0 | K28: 0 | L28: 0 | M28: 0 | N28: 0
A29: 9 | B29: P.2.1. Modelo de atención de los CCP actualizado, fortalecido, y en funcionamiento en los CCPs de la red | C29: # of agencies | D29: No | E29: P | F29: 0 | G29: 0 | H29: 0 | I29: 0 | J29: 0 | K29: 1 | L29: 0 | M29: 0 | N29: 1
A30: 9 | E30: P(a) | F30: 0 | G30: 0 | H30: 0 | I30: 0 | J30: 0 | K30: 0 | L30: 1 | M30: 0 | N30: 1
A31: 9 | E31: A | F31: 0 | G31: 0 | H31: 0 | I31: 0 | J31: 0 | K31: 0 | L31: 0 | M31: 0 | N31: 0
A32: 10 | B32: P.2.2. Modelo de gestión de los CCP homologado, fortalecido y en funcionamiento en los CCPs de la red | C32: # of agencies | D32: No | E32: P | F32: 0 | G32: 0 | H32: 0 | I32: 0 | J32: 0 | K32: 1 | L32: 0 | M32: 0 | N32: 1
A33: 10 | E33: P(a) | F33: 0 | G33: 0 | H33: 0 | I33: 0 | J33: 0 | K33: 0 | L33: 1 | M33: 0 | N33: 1
A34: 10 | E34: A | F34: 0 | G34: 0 | H34: 0 | I34: 0 | J34: 0 | K34: 0 | L34: 0 | M34: 0 | N34: 0
A35: 11 | B35: P.2.3. Municipalidades y grupos de sociedad civil capacitados y utilizando las nuevas competencias adquiridas en prevención de violencia | C35: # | D35: No | E35: P | F35: 0 | G35: 0 | H35: 3 | I35: 4 | J35: 4 | K35: 4 | L35: 0 | M35: 0 | N35: 15
A36: 11 | E36: P(a) | F36: 0 | G36: 0 | H36: 3 | I36: 4 | J36: 4 | K36: 4 | L36: 0 | M36: 0 | N36: 15
A37: 11 | E37: A | F37: 0 | G37: 0 | H37: 1 | I37: 6 | J37: 4 | K37: 4 | L37: 0 | M37: 0 | N37: 15
A38: 12 | B38: P.2.4. Estrategia de comunicación social de los CCP, diseñada e implementada | C38: # of agencies | D38: No | E38: P | F38: 0 | G38: 0 | H38: 0 | I38: 0 | J38: 1 | K38: 0 | L38: 0 | M38: 0 | N38: 1
A39: 12 | E39: P(a) | F39: 0 | G39: 0 | H39: 0 | I39: 0 | J39: 1 | K39: 0 | L39: 0 | M39: 0 | N39: 1
A40: 12 | E40: A | F40: 0 | G40: 0 | H40: 0 | I40: 0 | J40: 1 | K40: 0 | L40: 0 | M40: 0 | N40: 1
A41: 13 | B41: P.2.5. Sistema de información integrado de los CCP, desarrollado e implementado | C41: # of agencies | D41: No | E41: P | F41: 0 | G41: 0 | H41: 0 | I41: 0 | J41: 1 | K41: 0 | L41: 0 | M41: 0 | N41: 1
A42: 13 | E42: P(a) | F42: 0 | G42: 0 | H42: 0 | I42: 0 | J42: 0 | K42: 1 | L42: 1 | M42: 0 | N42: 1
...

Sheet Financiero
A1: Datos financieros (US$) por producto – base PMR I semestre 2026 (fuente: simulador oficial)
A4: Nro | B4: Producto | C4: Unidad | D4: ¿Por hitos? | E4: Tipo | F4: 2020 | G4: 2021 | H4: 2022 | I4: 2023 | J4: 2024 | K4: 2025 | L4: 2026 | M4: 2027 | N4: EOP
A5: 1 | B5: P1.1. Plataformas de datos policiales integradas e interoperables | C5: # of agencies | D5: No | E5: P | F5: 0 | G5: 0 | H5: 0 | I5: 64891 | J5: 693120 | K5: 0 | L5: 0 | M5: 0 | N5: 758011
A6: 1 | E6: P(a) | F6: 0 | G6: 0 | H6: 0 | I6: 195000 | J6: 255976 | K6: 0 | L6: 0 | M6: 0 | N6: 224656.16
A7: 1 | E7: A | F7: 0 | G7: 0 | H7: 17510 | I7: 4680 | J7: 202466.16 | K7: 0 | L7: 0 | M7: 0 | N7: 224656.16
A8: 2 | B8: P1.2. Sistema de información delictual fortalecidos y en funcionamiento | C8: # of agencies | D8: No | E8: P | F8: 0 | G8: 0 | H8: 0 | I8: 67500 | J8: 2979157 | K8: 57800 | L8: 0 | M8: 0 | N8: 3104457
A9: 2 | E9: P(a) | F9: 0 | G9: 0 | H9: 0 | I9: 0 | J9: 4680 | K9: 0 | L9: 0 | M9: 0 | N9: 23360
A10: 2 | E10: A | F10: 0 | G10: 0 | H10: 17510 | I10: 4680 | J10: 1170 | K10: 0 | L10: 0 | M10: 0 | N10: 23360
A11: 3 | B11: P.1.3. Departamentos de la FP capacitados en análisis criminal y monitoreo de dinámicas delictivas | C11: # de departamentos | D11: No | E11: P | F11: 0 | G11: 0 | H11: 0 | I11: 13500 | J11: 220500 | K11: 66000 | L11: 0 | M11: 0 | N11: 300000
A12: 3 | E12: P(a) | F12: 0 | G12: 0 | H12: 0 | I12: 151348 | J12: 62513 | K12: 0 | L12: 0 | M12: 0 | N12: 140489.6
A13: 3 | E13: A | F13: 0 | G13: 0 | H13: 34226.5 | I13: 96930.59 | J13: 9332.51 | K13: 0 | L13: 0 | M13: 0 | N13: 140489.6
A14: 4 | B14: P.1.4. Estrategias policiales basadas en evidencia diseñadas e implementadas | C14: # of agencies | D14: No | E14: P | F14: 0 | G14: 0 | H14: 36068 | I14: 442733 | J14: 977900 | K14: 146300 | L14: 0 | M14: 0 | N14: 1603001
A15: 4 | E15: P(a) | F15: 0 | G15: 0 | H15: 36068 | I15: 129352 | J15: 59013 | K15: 683150.38 | L15: 806934.43 | M15: 0 | N15: 1399764.2
A16: 4 | E16: A | F16: 0 | G16: 0 | H16: 34226.5 | I16: 83796.67 | J16: 164071.05 | K16: 310735.59 | L16: 242643.82 | M16: 0 | N16: 835473.63
A17: 5 | B17: P.1.5. Evaluación de impacto de estrategias policiales basadas en evidencia diseñada e implementada | C17: Evaluación | D17: No | E17: P | F17: 0 | G17: 0 | H17: 0 | I17: 0 | J17: 94167 | K17: 55833 | L17: 0 | M17: 0 | N17: 150000
A18: 5 | E18: P(a) | F18: 0 | G18: 0 | H18: 0 | I18: 0 | J18: 10000 | K18: 52848.33 | L18: 43162.5 | M18: 0 | N18: 130000
A19: 5 | E19: A | F19: 0 | G19: 0 | H19: 0 | I19: 0 | J19: 18375 | K19: 68462.5 | L19: 10800 | M19: 0 | N19: 97637.5
A20: 6 | B20: P.1.6. Sistema de procesamiento de quejas ciudadanas y procesos disciplinarios, fortalecido | C20: # of agencies | D20: No | E20: P | F20: 0 | G20: 0 | H20: 0 | I20: 40000 | J20: 144450 | K20: 65550 | L20: 0 | M20: 0 | N20: 250000
A21: 6 | E21: P(a) | F21: 0 | G21: 0 | H21: 0 | I21: 42990 | J21: 50813 | K21: 331486 | L21: 132506.09 | M21: 0 | N21: 365000
A22: 6 | E22: A | F22: 0 | G22: 0 | H22: 3510 | I22: 18580 | J22: 59200 | K22: 151203.91 | L22: 44753.04 | M22: 0 | N22: 277246.95
A23: 7 | B23: P.1.7. Delegaciones diseñadas, construida, equipadas y operando bajo el enfoque de policía comunitaria | C23: Subnational governments (#) | D23: Sí | E23: P | F23: 0 | G23: 0 | H23: 1890878 | I23: 5454037 | J23: 16701808 | K23: 20600459 | L23: 12187349 | M23: 0 | N23: 56834531
A24: 7 | E24: P(a) | F24: 0 | G24: 0 | H24: 1890878 | I24: 8434713.3 | J24: 22340305 | K24: 12762871 | L24: 16810688 | M24: 6661621.8 | N24: 56834530
A25: 7 | E25: A | F25: 0 | G25: 0 | H25: 400247 | I25: 4173815.5 | J25: 13528671 | K25: 15259487 | L25: 12836196 | M25: 0 | N25: 46198416
A26: 8 | B26: Centro de Mando y Control Policial (CMCP) diseñado, construido, equipado y en funcionamiento | C26: Número | D26: No | E26: P | F26: 0 | G26: 0 | H26: 0 | I26: 0 | J26: 0 | K26: 0 | L26: 0 | M26: 0 | N26: 0
A27: 8 | E27: P(a) | F27: 0 | G27: 0 | H27: 0 | I27: 0 | J27: 0 | K27: 607500 | L27: 2247328.9 | M27: 719443.75 | N27: 3882200
A28: 8 | E28: A | F28: 0 | G28: 0 | H28: 0 | I28: 0 | J28: 0 | K28: 915427.4 | L28: 1583816.3 | M28: 0 | N28: 2499243.7
A29: 9 | B29: P.2.1. Modelo de atención de los CCP actualizado, fortalecido, y en funcionamiento en los CCPs de la red | C29: # of agencies | D29: No | E29: P | F29: 0 | G29: 0 | H29: 28350 | I29: 105025 | J29: 105850 | K29: 60775 | L29: 0 | M29: 0 | N29: 300000
A30: 9 | E30: P(a) | F30: 0 | G30: 0 | H30: 28350 | I30: 10000 | J30: 63200 | K30: 232413.63 | L30: 228649.42 | M30: 0 | N30: 353000
A31: 9 | E31: A | F31: 0 | G31: 0 | H31: 0 | I31: 4578.73 | J31: 29506.28 | K31: 90265.57 | L31: 55564.52 | M31: 0 | N31: 179915.1
A32: 10 | B32: P.2.2. Modelo de gestión de los CCP homologado, fortalecido y en funcionamiento en los CCPs de la red | C32: # of agencies | D32: No | E32: P | F32: 0 | G32: 0 | H32: 8540 | I32: 78226 | J32: 44203 | K32: 14031 | L32: 0 | M32: 0 | N32: 145000
A33: 10 | E33: P(a) | F33: 0 | G33: 0 | H33: 8540 | I33: 4320 | J33: 10000 | K33: 46125 | L33: 141855 | M33: 0 | N33: 141855
A34: 10 | E34: A | F34: 0 | G34: 0 | H34: 0 | I34: 0 | J34: 0 | K34: 0 | L34: 0 | M34: 0 | N34: 0
A35: 11 | B35: P.2.3. Municipalidades y grupos de sociedad civil capacitados y utilizando las nuevas competencias adquiridas en prevención de violencia | C35: # | D35: No | E35: P | F35: 0 | G35: 0 | H35: 12482 | I35: 26790 | J35: 33513 | K35: 24715 | L35: 0 | M35: 0 | N35: 97500
A36: 11 | E36: P(a) | F36: 0 | G36: 0 | H36: 12482 | I36: 23335.75 | J36: 26558 | K36: 21428 | L36: 22748.16 | M36: 0 | N36: 97495
A37: 11 | E37: A | F37: 0 | G37: 0 | H37: 4709.25 | I37: 27998 | J37: 19254.59 | K37: 22785 | L37: 6300 | M37: 0 | N37: 81046.84
A38: 12 | B38: P.2.4. Estrategia de comunicación social de los CCP, diseñada e implementada | C38: # of agencies | D38: No | E38: P | F38: 0 | G38: 0 | H38: 0 | I38: 18696 | J38: 38652 | K38: 17652 | L38: 0 | M38: 0 | N38: 75000
A39: 12 | E39: P(a) | F39: 0 | G39: 0 | H39: 0 | I39: 13800 | J39: 41620 | K39: 42501.75 | L39: 56653 | M39: 0 | N39: 101393
A40: 12 | E40: A | F40: 0 | G40: 0 | H40: 1013 | I40: 11372 | J40: 14685 | K40: 17670 | L40: 1440 | M40: 0 | N40: 46180
A41: 13 | B41: P.2.5. Sistema de información integrado de los CCP, desarrollado e implementado | C41: # of agencies | D41: No | E41: P | F41: 0 | G41: 0 | H41: 7500 | I41: 68000 | J41: 12000 | K41: 0 | L41: 0 | M41: 0 | N41: 87500
A42: 13 | E42: P(a) | F42: 0 | G42: 0 | H42: 7500 | I42: 32600 | J42: 20950 | K42: 96086 | L42: 77492.5 | M42: 0 | N42: 109170
...

Sheet Hitos
A1: Hitos de productos por hitos – base PMR I semestre 2026 (fuente: reporte PMR, sección Milestones)
A4: Nro producto | B4: Hito | C4: Tipo | D4: 2020 | E4: 2021 | F4: 2022 | G4: 2023 | H4: 2024 | I4: 2025 | J4: 2026 | K4: 2027 | L4: Meta EOP | M4: Costo hito P (US$) | N4: Costo hito P(a) (US$)
A5: 7 | B5: Delegaciones Policiales diseñadas | C5: P | D5: 0 | E5: 0 | F5: 4 | G5: 7 | H5: 10 | I5: 14 | J5: 0 | K5: 0 | L5: 35 | M5: 4840000 | N5: 4840000
A6: 7 | C6: P(a) | D6: 0 | E6: 0 | F6: 4 | G6: 11 | H6: 11 | I6: 1 | J6: 0 | K6: 0 | L6: 21
A7: 7 | C7: A | D7: 0 | E7: 0 | F7: 5 | G7: 11 | H7: 5 | I7: 0 | J7: 0 | K7: 0 | L7: =SUM(D7:K7) -> 21
A8: 7 | B8: Delegaciones Policiales construidas, equipadas y operando | C8: P | D8: 0 | E8: 0 | F8: 0 | G8: 4 | H8: 7 | I8: 10 | J8: 14 | K8: 0 | L8: 35 | M8: 51994531 | N8: 51994530
A9: 7 | C9: P(a) | D9: 0 | E9: 0 | F9: 0 | G9: 2 | H9: 6 | I9: 2 | J9: 4 | K9: 6 | L9: 17
A10: 7 | C10: A | D10: 0 | E10: 0 | F10: 0 | G10: 1 | H10: 5 | I10: 1 | J10: 5 | K10: 0 | L10: =SUM(D10:K10) -> 12
A11: 15 | B11: CCPs diseñados | C11: P | D11: 0 | E11: 0 | F11: 1 | G11: 0 | H11: 3 | I11: 4 | J11: 0 | K11: 0 | L11: 8 | M11: 2300000 | N11: 2300000
A12: 15 | C12: P(a) | D12: 0 | E12: 0 | F12: 1 | G12: 4 | H12: 2 | I12: 2 | J12: 0 | K12: 0 | L12: 8
A13: 15 | C13: A | D13: 0 | E13: 0 | F13: 2 | G13: 4 | H13: 0 | I13: 2 | J13: 0 | K13: 0 | L13: =SUM(D13:K13) -> 8
A14: 15 | B14: CCPs construidos, equipados y en funcionamiento | C14: P | D14: 0 | E14: 0 | F14: 0 | G14: 0 | H14: 1 | I14: 3 | J14: 4 | K14: 0 | L14: 8 | M14: 28565000 | N14: 28565000
A15: 15 | C15: P(a) | D15: 0 | E15: 0 | F15: 0 | G15: 0 | H15: 3 | I15: 2 | J15: 1 | K15: 4 | L15: 8
A16: 15 | C16: A | D16: 0 | E16: 0 | F16: 0 | G16: 0 | H16: 1 | I16: 2 | J16: 1 | K16: 0 | L16: =SUM(D16:K16) -> 4
A17: 15 | B17: Techados de Skate Parks Garabito y Santa Cruz construidos | C17: P | D17: 0 | E17: 0 | F17: 0 | G17: 2 | H17: 0 | I17: 0 | J17: 0 | K17: 0 | L17: 2 | M17: 730000 | N17: 730000
A18: 15 | C18: P(a) | D18: 0 | E18: 0 | F18: 0 | G18: 2 | H18: 1 | I18: 0 | J18: 0 | K18: 0 | L18: 2
A19: 15 | C19: A | D19: 0 | E19: 0 | F19: 0 | G19: 1 | H19: 1 | I19: 0 | J19: 0 | K19: 0 | L19: =SUM(D19:K19) -> 2
B22: El EV de un hito usa la meta EOP P; el EV(a) usa la meta EOP P(a). Años en fila 4 (D:K).

Sheet Calculo
A1: Cálculo de PV, PV(a), AC, EV y EV(a) por producto y escenario (no editar)
A3: Escenario: Base | C3: =Escenarios!C5 -> Base PMR jun-2026
A4: Nro | B4: Producto | C4: ¿Hitos? | D4: PV | E4: PV(a) | F4: AC | G4: P físico acum. | H4: P(a) físico (año) | I4: A físico acum. | J4: %P | K4: %P(a) | L4: EV | M4: EV(a)
A5: 1 | B5: =Fisico!B5 -> P1.1. Plataformas de datos policiales integradas e interoperables | C5: =Fisico!D5 -> No | D5: =SUMPRODUCT((Financiero!$F$4:$M$4<=Parametros!$C$6)*Financiero!$F$5:$M$5) -> 758011 | E5: =SUMPRODUCT((Financiero!$F$4:$M$4<Parametros!$C$6)*Financiero!$F$7:$M$7)+SUMPRODUCT((Financiero!$F$4:$M$4=Parametros!$C$6)*Financiero!$F$6:$M$6) -> 224656.16 | F5: =SUMPRODUCT((Financiero!$F$4:$M$4<=Parametros!$C$6)*Financiero!$F$7:$M$7)+0 -> 224656.16 | G5: =SUMPRODUCT((Fisico!$F$4:$M$4<=Parametros!$C$6)*Fisico!$F$5:$M$5) -> 1 | H5: =SUMPRODUCT((Fisico!$F$4:$M$4<Parametros!$C$6)*Fisico!$F$7:$M$7)+SUMPRODUCT((Fisico!$F$4:$M$4=Parametros!$C$6)*Fisico!$F$6:$M$6) -> 0 | I5: =SUMPRODUCT((Fisico!$F$4:$M$4<=Parametros!$C$6)*Fisico!$F$7:$M$7)+0 -> 0 | J5: =IF(G5=0,"N/A",I5/G5) -> 0 | K5: =IF(H5=0,"N/A",I5/H5) -> N/A | L5: =IF(C5="Sí",SUMIF($A$25:$A$29,A5,$H$25:$H$29),IF(J5="N/A",F5,J5*D5)) -> 0 | M5: =IF(C5="Sí",SUMIF($A$25:$A$29,A5,$I$25:$I$29),IF(K5="N/A",F5,K5*E5)) -> 224656.16
A6: 2 | B6: =Fisico!B8 -> P1.2. Sistema de información delictual fortalecidos y en funcionamiento | C6: =Fisico!D8 -> No | D6: =SUMPRODUCT((Financiero!$F$4:$M$4<=Parametros!$C$6)*Financiero!$F$8:$M$8) -> 3104457 | E6: =SUMPRODUCT((Financiero!$F$4:$M$4<Parametros!$C$6)*Financiero!$F$10:$M$10)+SUMPRODUCT((Financiero!$F$4:$M$4=Parametros!$C$6)*Financiero!$F$9:$M$9) -> 23360 | F6: =SUMPRODUCT((Financiero!$F$4:$M$4<=Parametros!$C$6)*Financiero!$F$10:$M$10)+0 -> 23360 | G6: =SUMPRODUCT((Fisico!$F$4:$M$4<=Parametros!$C$6)*Fisico!$F$8:$M$8) -> 1 | H6: =SUMPRODUCT((Fisico!$F$4:$M$4<Parametros!$C$6)*Fisico!$F$10:$M$10)+SUMPRODUCT((Fisico!$F$4:$M$4=Parametros!$C$6)*Fisico!$F$9:$M$9) -> 0 | I6: =SUMPRODUCT((Fisico!$F$4:$M$4<=Parametros!$C$6)*Fisico!$F$10:$M$10)+0 -> 0 | J6: =IF(G6=0,"N/A",I6/G6) -> 0 | K6: =IF(H6=0,"N/A",I6/H6) -> N/A | L6: =IF(C6="Sí",SUMIF($A$25:$A$29,A6,$H$25:$H$29),IF(J6="N/A",F6,J6*D6)) -> 0 | M6: =IF(C6="Sí",SUMIF($A$25:$A$29,A6,$I$25:$I$29),IF(K6="N/A",F6,K6*E6)) -> 23360
A7: 3 | B7: =Fisico!B11 -> P.1.3. Departamentos de la FP capacitados en análisis criminal y monitoreo de dinámicas delictivas | C7: =Fisico!D11 -> No | D7: =SUMPRODUCT((Financiero!$F$4:$M$4<=Parametros!$C$6)*Financiero!$F$11:$M$11) -> 300000 | E7: =SUMPRODUCT((Financiero!$F$4:$M$4<Parametros!$C$6)*Financiero!$F$13:$M$13)+SUMPRODUCT((Financiero!$F$4:$M$4=Parametros!$C$6)*Financiero!$F$12:$M$12) -> 140489.6 | F7: =SUMPRODUCT((Financiero!$F$4:$M$4<=Parametros!$C$6)*Financiero!$F$13:$M$13)+0 -> 140489.6 | G7: =SUMPRODUCT((Fisico!$F$4:$M$4<=Parametros!$C$6)*Fisico!$F$11:$M$11) -> 16 | H7: =SUMPRODUCT((Fisico!$F$4:$M$4<Parametros!$C$6)*Fisico!$F$13:$M$13)+SUMPRODUCT((Fisico!$F$4:$M$4=Parametros!$C$6)*Fisico!$F$12:$M$12) -> 29 | I7: =SUMPRODUCT((Fisico!$F$4:$M$4<=Parametros!$C$6)*Fisico!$F$13:$M$13)+0 -> 29 | J7: =IF(G7=0,"N/A",I7/G7) -> 1.8125 | K7: =IF(H7=0,"N/A",I7/H7) -> 1 | L7: =IF(C7="Sí",SUMIF($A$25:$A$29,A7,$H$25:$H$29),IF(J7="N/A",F7,J7*D7)) -> 543750 | M7: =IF(C7="Sí",SUMIF($A$25:$A$29,A7,$I$25:$I$29),IF(K7="N/A",F7,K7*E7)) -> 140489.6
A8: 4 | B8: =Fisico!B14 -> P.1.4. Estrategias policiales basadas en evidencia diseñadas e implementadas | C8: =Fisico!D14 -> No | D8: =SUMPRODUCT((Financiero!$F$4:$M$4<=Parametros!$C$6)*Financiero!$F$14:$M$14) -> 1603001 | E8: =SUMPRODUCT((Financiero!$F$4:$M$4<Parametros!$C$6)*Financiero!$F$16:$M$16)+SUMPRODUCT((Financiero!$F$4:$M$4=Parametros!$C$6)*Financiero!$F$15:$M$15) -> 1399764.2 | F8: =SUMPRODUCT((Financiero!$F$4:$M$4<=Parametros!$C$6)*Financiero!$F$16:$M$16)+0 -> 835473.63 | G8: =SUMPRODUCT((Fisico!$F$4:$M$4<=Parametros!$C$6)*Fisico!$F$14:$M$14) -> 1 | H8: =SUMPRODUCT((Fisico!$F$4:$M$4<Parametros!$C$6)*Fisico!$F$16:$M$16)+SUMPRODUCT((Fisico!$F$4:$M$4=Parametros!$C$6)*Fisico!$F$15:$M$15) -> 1 | I8: =SUMPRODUCT((Fisico!$F$4:$M$4<=Parametros!$C$6)*Fisico!$F$16:$M$16)+0 -> 0 | J8: =IF(G8=0,"N/A",I8/G8) -> 0 | K8: =IF(H8=0,"N/A",I8/H8) -> 0 | L8: =IF(C8="Sí",SUMIF($A$25:$A$29,A8,$H$25:$H$29),IF(J8="N/A",F8,J8*D8)) -> 0 | M8: =IF(C8="Sí",SUMIF($A$25:$A$29,A8,$I$25:$I$29),IF(K8="N/A",F8,K8*E8)) -> 0
A9: 5 | B9: =Fisico!B17 -> P.1.5. Evaluación de impacto de estrategias policiales basadas en evidencia diseñada e implementada | C9: =Fisico!D17 -> No | D9: =SUMPRODUCT((Financiero!$F$4:$M$4<=Parametros!$C$6)*Financiero!$F$17:$M$17) -> 150000 | E9: =SUMPRODUCT((Financiero!$F$4:$M$4<Parametros!$C$6)*Financiero!$F$19:$M$19)+SUMPRODUCT((Financiero!$F$4:$M$4=Parametros!$C$6)*Financiero!$F$18:$M$18) -> 130000 | F9: =SUMPRODUCT((Financiero!$F$4:$M$4<=Parametros!$C$6)*Financiero!$F$19:$M$19)+0 -> 97637.5 | G9: =SUMPRODUCT((Fisico!$F$4:$M$4<=Parametros!$C$6)*Fisico!$F$17:$M$17) -> 1 | H9: =SUMPRODUCT((Fisico!$F$4:$M$4<Parametros!$C$6)*Fisico!$F$19:$M$19)+SUMPRODUCT((Fisico!$F$4:$M$4=Parametros!$C$6)*Fisico!$F$18:$M$18) -> 1 | I9: =SUMPRODUCT((Fisico!$F$4:$M$4<=Parametros!$C$6)*Fisico!$F$19:$M$19)+0 -> 0 | J9: =IF(G9=0,"N/A",I9/G9) -> 0 | K9: =IF(H9=0,"N/A",I9/H9) -> 0 | L9: =IF(C9="Sí",SUMIF($A$25:$A$29,A9,$H$25:$H$29),IF(J9="N/A",F9,J9*D9)) -> 0 | M9: =IF(C9="Sí",SUMIF($A$25:$A$29,A9,$I$25:$I$29),IF(K9="N/A",F9,K9*E9)) -> 0
A10: 6 | B10: =Fisico!B20 -> P.1.6. Sistema de procesamiento de quejas ciudadanas y procesos disciplinarios, fortalecido | C10: =Fisico!D20 -> No | D10: =SUMPRODUCT((Financiero!$F$4:$M$4<=Parametros!$C$6)*Financiero!$F$20:$M$20) -> 250000 | E10: =SUMPRODUCT((Financiero!$F$4:$M$4<Parametros!$C$6)*Financiero!$F$22:$M$22)+SUMPRODUCT((Financiero!$F$4:$M$4=Parametros!$C$6)*Financiero!$F$21:$M$21) -> 365000 | F10: =SUMPRODUCT((Financiero!$F$4:$M$4<=Parametros!$C$6)*Financiero!$F$22:$M$22)+0 -> 277246.95 | G10: =SUMPRODUCT((Fisico!$F$4:$M$4<=Parametros!$C$6)*Fisico!$F$20:$M$20) -> 1 | H10: =SUMPRODUCT((Fisico!$F$4:$M$4<Parametros!$C$6)*Fisico!$F$22:$M$22)+SUMPRODUCT((Fisico!$F$4:$M$4=Parametros!$C$6)*Fisico!$F$21:$M$21) -> 1 | I10: =SUMPRODUCT((Fisico!$F$4:$M$4<=Parametros!$C$6)*Fisico!$F$22:$M$22)+0 -> 0 | J10: =IF(G10=0,"N/A",I10/G10) -> 0 | K10: =IF(H10=0,"N/A",I10/H10) -> 0 | L10: =IF(C10="Sí",SUMIF($A$25:$A$29,A10,$H$25:$H$29),IF(J10="N/A",F10,J10*D10)) -> 0 | M10: =IF(C10="Sí",SUMIF($A$25:$A$29,A10,$I$25:$I$29),IF(K10="N/A",F10,K10*E10)) -> 0
A11: 7 | B11: =Fisico!B23 -> P.1.7. Delegaciones diseñadas, construida, equipadas y operando bajo el enfoque de policía comunitaria | C11: =Fisico!D23 -> Sí | D11: =SUMPRODUCT((Financiero!$F$4:$M$4<=Parametros!$C$6)*Financiero!$F$23:$M$23) -> 56834531 | E11: =SUMPRODUCT((Financiero!$F$4:$M$4<Parametros!$C$6)*Financiero!$F$25:$M$25)+SUMPRODUCT((Financiero!$F$4:$M$4=Parametros!$C$6)*Financiero!$F$24:$M$24) -> 50172908 | F11: =SUMPRODUCT((Financiero!$F$4:$M$4<=Parametros!$C$6)*Financiero!$F$25:$M$25)+0 -> 46198416 | G11: =SUMPRODUCT((Fisico!$F$4:$M$4<=Parametros!$C$6)*Fisico!$F$23:$M$23) -> 35 | H11: =SUMPRODUCT((Fisico!$F$4:$M$4<Parametros!$C$6)*Fisico!$F$25:$M$25)+SUMPRODUCT((Fisico!$F$4:$M$4=Parametros!$C$6)*Fisico!$F$24:$M$24) -> 11 | I11: =SUMPRODUCT((Fisico!$F$4:$M$4<=Parametros!$C$6)*Fisico!$F$25:$M$25)+0 -> 15 | J11: =IF(G11=0,"N/A",I11/G11) -> 0.42857143 | K11: =IF(H11=0,"N/A",I11/H11) -> 1.3636364 | L11: =IF(C11="Sí",SUMIF($A$25:$A$29,A11,$H$25:$H$29),IF(J11="N/A",F11,J11*D11)) -> 20730696 | M11: =IF(C11="Sí",SUMIF($A$25:$A$29,A11,$I$25:$I$29),IF(K11="N/A",F11,K11*E11)) -> 41542021
A12: 8 | B12: =Fisico!B26 -> Centro de Mando y Control Policial (CMCP) diseñado, construido, equipado y en funcionamiento | C12: =Fisico!D26 -> No | D12: =SUMPRODUCT((Financiero!$F$4:$M$4<=Parametros!$C$6)*Financiero!$F$26:$M$26) -> 0 | E12: =SUMPRODUCT((Financiero!$F$4:$M$4<Parametros!$C$6)*Financiero!$F$28:$M$28)+SUMPRODUCT((Financiero!$F$4:$M$4=Parametros!$C$6)*Financiero!$F$27:$M$27) -> 3162756.2 | F12: =SUMPRODUCT((Financiero!$F$4:$M$4<=Parametros!$C$6)*Financiero!$F$28:$M$28)+0 -> 2499243.7 | G12: =SUMPRODUCT((Fisico!$F$4:$M$4<=Parametros!$C$6)*Fisico!$F$26:$M$26) -> 0 | H12: =SUMPRODUCT((Fisico!$F$4:$M$4<Parametros!$C$6)*Fisico!$F$28:$M$28)+SUMPRODUCT((Fisico!$F$4:$M$4=Parametros!$C$6)*Fisico!$F$27:$M$27) -> 0 | I12: =SUMPRODUCT((Fisico!$F$4:$M$4<=Parametros!$C$6)*Fisico!$F$28:$M$28)+0 -> 0 | J12: =IF(G12=0,"N/A",I12/G12) -> N/A | K12: =IF(H12=0,"N/A",I12/H12) -> N/A | L12: =IF(C12="Sí",SUMIF($A$25:$A$29,A12,$H$25:$H$29),IF(J12="N/A",F12,J12*D12)) -> 2499243.7 | M12: =IF(C12="Sí",SUMIF($A$25:$A$29,A12,$I$25:$I$29),IF(K12="N/A",F12,K12*E12)) -> 2499243.7
A13: 9 | B13: =Fisico!B29 -> P.2.1. Modelo de atención de los CCP actualizado, fortalecido, y en funcionamiento en los CCPs de la red | C13: =Fisico!D29 -> No | D13: =SUMPRODUCT((Financiero!$F$4:$M$4<=Parametros!$C$6)*Financiero!$F$29:$M$29) -> 300000 | E13: =SUMPRODUCT((Financiero!$F$4:$M$4<Parametros!$C$6)*Financiero!$F$31:$M$31)+SUMPRODUCT((Financiero!$F$4:$M$4=Parametros!$C$6)*Financiero!$F$30:$M$30) -> 353000 | F13: =SUMPRODUCT((Financiero!$F$4:$M$4<=Parametros!$C$6)*Financiero!$F$31:$M$31)+0 -> 179915.1 | G13: =SUMPRODUCT((Fisico!$F$4:$M$4<=Parametros!$C$6)*Fisico!$F$29:$M$29) -> 1 | H13: =SUMPRODUCT((Fisico!$F$4:$M$4<Parametros!$C$6)*Fisico!$F$31:$M$31)+SUMPRODUCT((Fisico!$F$4:$M$4=Parametros!$C$6)*Fisico!$F$30:$M$30) -> 1 | I13: =SUMPRODUCT((Fisico!$F$4:$M$4<=Parametros!$C$6)*Fisico!$F$31:$M$31)+0 -> 0 | J13: =IF(G13=0,"N/A",I13/G13) -> 0 | K13: =IF(H13=0,"N/A",I13/H13) -> 0 | L13: =IF(C13="Sí",SUMIF($A$25:$A$29,A13,$H$25:$H$29),IF(J13="N/A",F13,J13*D13)) -> 0 | M13: =IF(C13="Sí",SUMIF($A$25:$A$29,A13,$I$25:$I$29),IF(K13="N/A",F13,K13*E13)) -> 0
A14: 10 | B14: =Fisico!B32 -> P.2.2. Modelo de gestión de los CCP homologado, fortalecido y en funcionamiento en los CCPs de la red | C14: =Fisico!D32 -> No | D14: =SUMPRODUCT((Financiero!$F$4:$M$4<=Parametros!$C$6)*Financiero!$F$32:$M$32) -> 145000 | E14: =SUMPRODUCT((Financiero!$F$4:$M$4<Parametros!$C$6)*Financiero!$F$34:$M$34)+SUMPRODUCT((Financiero!$F$4:$M$4=Parametros!$C$6)*Financiero!$F$33:$M$33) -> 141855 | F14: =SUMPRODUCT((Financiero!$F$4:$M$4<=Parametros!$C$6)*Financiero!$F$34:$M$34)+0 -> 0 | G14: =SUMPRODUCT((Fisico!$F$4:$M$4<=Parametros!$C$6)*Fisico!$F$32:$M$32) -> 1 | H14: =SUMPRODUCT((Fisico!$F$4:$M$4<Parametros!$C$6)*Fisico!$F$34:$M$34)+SUMPRODUCT((Fisico!$F$4:$M$4=Parametros!$C$6)*Fisico!$F$33:$M$33) -> 1 | I14: =SUMPRODUCT((Fisico!$F$4:$M$4<=Parametros!$C$6)*Fisico!$F$34:$M$34)+0 -> 0 | J14: =IF(G14=0,"N/A",I14/G14) -> 0 | K14: =IF(H14=0,"N/A",I14/H14) -> 0 | L14: =IF(C14="Sí",SUMIF($A$25:$A$29,A14,$H$25:$H$29),IF(J14="N/A",F14,J14*D14)) -> 0 | M14: =IF(C14="Sí",SUMIF($A$25:$A$29,A14,$I$25:$I$29),IF(K14="N/A",F14,K14*E14)) -> 0
A15: 11 | B15: =Fisico!B35 -> P.2.3. Municipalidades y grupos de sociedad civil capacitados y utilizando las nuevas competencias adquiridas en prevención de violencia | C15: =Fisico!D35 -> No | D15: =SUMPRODUCT((Financiero!$F$4:$M$4<=Parametros!$C$6)*Financiero!$F$35:$M$35) -> 97500 | E15: =SUMPRODUCT((Financiero!$F$4:$M$4<Parametros!$C$6)*Financiero!$F$37:$M$37)+SUMPRODUCT((Financiero!$F$4:$M$4=Parametros!$C$6)*Financiero!$F$36:$M$36) -> 97495 | F15: =SUMPRODUCT((Financiero!$F$4:$M$4<=Parametros!$C$6)*Financiero!$F$37:$M$37)+0 -> 81046.84 | G15: =SUMPRODUCT((Fisico!$F$4:$M$4<=Parametros!$C$6)*Fisico!$F$35:$M$35) -> 15 | H15: =SUMPRODUCT((Fisico!$F$4:$M$4<Parametros!$C$6)*Fisico!$F$37:$M$37)+SUMPRODUCT((Fisico!$F$4:$M$4=Parametros!$C$6)*Fisico!$F$36:$M$36) -> 15 | I15: =SUMPRODUCT((Fisico!$F$4:$M$4<=Parametros!$C$6)*Fisico!$F$37:$M$37)+0 -> 15 | J15: =IF(G15=0,"N/A",I15/G15) -> 1 | K15: =IF(H15=0,"N/A",I15/H15) -> 1 | L15: =IF(C15="Sí",SUMIF($A$25:$A$29,A15,$H$25:$H$29),IF(J15="N/A",F15,J15*D15)) -> 97500 | M15: =IF(C15="Sí",SUMIF($A$25:$A$29,A15,$I$25:$I$29),IF(K15="N/A",F15,K15*E15)) -> 97495
A16: 12 | B16: =Fisico!B38 -> P.2.4. Estrategia de comunicación social de los CCP, diseñada e implementada | C16: =Fisico!D38 -> No | D16: =SUMPRODUCT((Financiero!$F$4:$M$4<=Parametros!$C$6)*Financiero!$F$38:$M$38) -> 75000 | E16: =SUMPRODUCT((Financiero!$F$4:$M$4<Parametros!$C$6)*Financiero!$F$40:$M$40)+SUMPRODUCT((Financiero!$F$4:$M$4=Parametros!$C$6)*Financiero!$F$39:$M$39) -> 101393 | F16: =SUMPRODUCT((Financiero!$F$4:$M$4<=Parametros!$C$6)*Financiero!$F$40:$M$40)+0 -> 46180 | G16: =SUMPRODUCT((Fisico!$F$4:$M$4<=Parametros!$C$6)*Fisico!$F$38:$M$38) -> 1 | H16: =SUMPRODUCT((Fisico!$F$4:$M$4<Parametros!$C$6)*Fisico!$F$40:$M$40)+SUMPRODUCT((Fisico!$F$4:$M$4=Parametros!$C$6)*Fisico!$F$39:$M$39) -> 1 | I16: =SUMPRODUCT((Fisico!$F$4:$M$4<=Parametros!$C$6)*Fisico!$F$40:$M$40)+0 -> 1 | J16: =IF(G16=0,"N/A",I16/G16) -> 1 | K16: =IF(H16=0,"N/A",I16/H16) -> 1 | L16: =IF(C16="Sí",SUMIF($A$25:$A$29,A16,$H$25:$H$29),IF(J16="N/A",F16,J16*D16)) -> 75000 | M16: =IF(C16="Sí",SUMIF($A$25:$A$29,A16,$I$25:$I$29),IF(K16="N/A",F16,K16*E16)) -> 101393
A17: 13 | B17: =Fisico!B41 -> P.2.5. Sistema de información integrado de los CCP, desarrollado e implementado | C17: =Fisico!D41 -> No | D17: =SUMPRODUCT((Financiero!$F$4:$M$4<=Parametros!$C$6)*Financiero!$F$41:$M$41) -> 87500 | E17: =SUMPRODUCT((Financiero!$F$4:$M$4<Parametros!$C$6)*Financiero!$F$43:$M$43)+SUMPRODUCT((Financiero!$F$4:$M$4=Parametros!$C$6)*Financiero!$F$42:$M$42) -> 109170 | F17: =SUMPRODUCT((Financiero!$F$4:$M$4<=Parametros!$C$6)*Financiero!$F$43:$M$43)+0 -> 99715 | G17: =SUMPRODUCT((Fisico!$F$4:$M$4<=Parametros!$C$6)*Fisico!$F$41:$M$41) -> 1 | H17: =SUMPRODUCT((Fisico!$F$4:$M$4<Parametros!$C$6)*Fisico!$F$43:$M$43)+SUMPRODUCT((Fisico!$F$4:$M$4=Parametros!$C$6)*Fisico!$F$42:$M$42) -> 1 | I17: =SUMPRODUCT((Fisico!$F$4:$M$4<=Parametros!$C$6)*Fisico!$F$43:$M$43)+0 -> 0 | J17: =IF(G17=0,"N/A",I17/G17) -> 0 | K17: =IF(H17=0,"N/A",I17/H17) -> 0 | L17: =IF(C17="Sí",SUMIF($A$25:$A$29,A17,$H$25:$H$29),IF(J17="N/A",F17,J17*D17)) -> 0 | M17: =IF(C17="Sí",SUMIF($A$25:$A$29,A17,$I$25:$I$29),IF(K17="N/A",F17,K17*E17)) -> 0
A18: 14 | B18: =Fisico!B44 -> P.2.6. Evaluación de impacto de los CCP diseñada e implementada | C18: =Fisico!D44 -> No | D18: =SUMPRODUCT((Financiero!$F$4:$M$4<=Parametros!$C$6)*Financiero!$F$44:$M$44) -> 200000 | E18: =SUMPRODUCT((Financiero!$F$4:$M$4<Parametros!$C$6)*Financiero!$F$46:$M$46)+SUMPRODUCT((Financiero!$F$4:$M$4=Parametros!$C$6)*Financiero!$F$45:$M$45) -> 102087 | F18: =SUMPRODUCT((Financiero!$F$4:$M$4<=Parametros!$C$6)*Financiero!$F$46:$M$46)+0 -> 13887.5 | G18: =SUMPRODUCT((Fisico!$F$4:$M$4<=Parametros!$C$6)*Fisico!$F$44:$M$44) -> 1 | H18: =SUMPRODUCT((Fisico!$F$4:$M$4<Parametros!$C$6)*Fisico!$F$46:$M$46)+SUMPRODUCT((Fisico!$F$4:$M$4=Parametros!$C$6)*Fisico!$F$45:$M$45) -> 1 | I18: =SUMPRODUCT((Fisico!$F$4:$M$4<=Parametros!$C$6)*Fisico!$F$46:$M$46)+0 -> 0 | J18: =IF(G18=0,"N/A",I18/G18) -> 0 | K18: =IF(H18=0,"N/A",I18/H18) -> 0 | L18: =IF(C18="Sí",SUMIF($A$25:$A$29,A18,$H$25:$H$29),IF(J18="N/A",F18,J18*D18)) -> 0 | M18: =IF(C18="Sí",SUMIF($A$25:$A$29,A18,$I$25:$I$29),IF(K18="N/A",F18,K18*E18)) -> 0
A19: 15 | B19: =Fisico!B47 -> P.2.7. CCP diseñados, construidos, equipados y en funcionamiento | C19: =Fisico!D47 -> Sí | D19: =SUMPRODUCT((Financiero!$F$4:$M$4<=Parametros!$C$6)*Financiero!$F$47:$M$47) -> 31595000 | E19: =SUMPRODUCT((Financiero!$F$4:$M$4<Parametros!$C$6)*Financiero!$F$49:$M$49)+SUMPRODUCT((Financiero!$F$4:$M$4=Parametros!$C$6)*Financiero!$F$48:$M$48) -> 27741937 | F19: =SUMPRODUCT((Financiero!$F$4:$M$4<=Parametros!$C$6)*Financiero!$F$49:$M$49)+0 -> 22823824 | G19: =SUMPRODUCT((Fisico!$F$4:$M$4<=Parametros!$C$6)*Fisico!$F$47:$M$47) -> 8 | H19: =SUMPRODUCT((Fisico!$F$4:$M$4<Parametros!$C$6)*Fisico!$F$49:$M$49)+SUMPRODUCT((Fisico!$F$4:$M$4=Parametros!$C$6)*Fisico!$F$48:$M$48) -> 4 | I19: =SUMPRODUCT((Fisico!$F$4:$M$4<=Parametros!$C$6)*Fisico!$F$49:$M$49)+0 -> 4 | J19: =IF(G19=0,"N/A",I19/G19) -> 0.5 | K19: =IF(H19=0,"N/A",I19/H19) -> 1 | L19: =IF(C19="Sí",SUMIF($A$25:$A$29,A19,$H$25:$H$29),IF(J19="N/A",F19,J19*D19)) -> 17312500 | M19: =IF(C19="Sí",SUMIF($A$25:$A$29,A19,$I$25:$I$29),IF(K19="N/A",F19,K19*E19)) -> 17312500
B20: TOTAL (regla: si la suma de PV o PV(a) es 0 se usa AC) | D20: =IF(SUM(D5:D19)=0,F20,SUM(D5:D19)) -> 95500000 | E20: =IF(SUM(E5:E19)=0,F20,SUM(E5:E19)) -> 84265872 | F20: =SUM(F5:F19) -> 73541092 | L20: =IF(SUM(D5:D19)=0,F20,SUM(L5:L19)) -> 41258690 | M20: =IF(SUM(E5:E19)=0,F20,SUM(M5:M19)) -> 61941159
A24: Nro producto | B24: Hito | C24: A acum. base | D24: A adicional | E24: A acum. | F24: Meta EOP P | G24: Meta EOP P(a) | H24: EV hito | I24: EV(a) hito
A25: =Hitos!A5 -> 7 | B25: =Hitos!B5 -> Delegaciones Policiales diseñadas | C25: =SUMPRODUCT((Hitos!$D$4:$K$4<=Parametros!$C$6)*Hitos!$D$7:$K$7) -> 21 | D25: 0 | E25: =C25+D25 -> 21 | F25: =Hitos!L5 -> 35 | G25: =Hitos!L6 -> 21 | H25: =IF(F25=0,0,E25/F25*Hitos!M5) -> 2904000 | I25: =IF(G25=0,0,E25/G25*Hitos!N5) -> 4840000
A26: =Hitos!A8 -> 7 | B26: =Hitos!B8 -> Delegaciones Policiales construidas, equipadas y operando | C26: =SUMPRODUCT((Hitos!$D$4:$K$4<=Parametros!$C$6)*Hitos!$D$10:$K$10) -> 12 | D26: 0 | E26: =C26+D26 -> 12 | F26: =Hitos!L8 -> 35 | G26: =Hitos!L9 -> 17 | H26: =IF(F26=0,0,E26/F26*Hitos!M8) -> 17826696 | I26: =IF(G26=0,0,E26/G26*Hitos!N8) -> 36702021
A27: =Hitos!A11 -> 15 | B27: =Hitos!B11 -> CCPs diseñados | C27: =SUMPRODUCT((Hitos!$D$4:$K$4<=Parametros!$C$6)*Hitos!$D$13:$K$13) -> 8 | D27: 0 | E27: =C27+D27 -> 8 | F27: =Hitos!L11 -> 8 | G27: =Hitos!L12 -> 8 | H27: =IF(F27=0,0,E27/F27*Hitos!M11) -> 2300000 | I27: =IF(G27=0,0,E27/G27*Hitos!N11) -> 2300000
A28: =Hitos!A14 -> 15 | B28: =Hitos!B14 -> CCPs construidos, equipados y en funcionamiento | C28: =SUMPRODUCT((Hitos!$D$4:$K$4<=Parametros!$C$6)*Hitos!$D$16:$K$16) -> 4 | D28: 0 | E28: =C28+D28 -> 4 | F28: =Hitos!L14 -> 8 | G28: =Hitos!L15 -> 8 | H28: =IF(F28=0,0,E28/F28*Hitos!M14) -> 14282500 | I28: =IF(G28=0,0,E28/G28*Hitos!N14) -> 14282500
A29: =Hitos!A17 -> 15 | B29: =Hitos!B17 -> Techados de Skate Parks Garabito y Santa Cruz construidos | C29: =SUMPRODUCT((Hitos!$D$4:$K$4<=Parametros!$C$6)*Hitos!$D$19:$K$19) -> 2 | D29: 0 | E29: =C29+D29 -> 2 | F29: =Hitos!L17 -> 2 | G29: =Hitos!L18 -> 2 | H29: =IF(F29=0,0,E29/F29*Hitos!M17) -> 730000 | I29: =IF(G29=0,0,E29/G29*Hitos!N17) -> 730000
A35: Escenario: E1 | C35: =Escenarios!D5 -> Cierre 2026 sin cambios
A36: Nro | B36: Producto | C36: ¿Hitos? | D36: PV | E36: PV(a) | F36: AC | G36: P físico acum. | H36: P(a) físico (año) | I36: A físico acum. | J36: %P | K36: %P(a) | L36: EV | M36: EV(a)
A37: 1 | B37: =Fisico!B5 -> P1.1. Plataformas de datos policiales integradas e interoperables | C37: =Fisico!D5 -> No | D37: =SUMPRODUCT((Financiero!$F$4:$M$4<=Parametros!$C$6)*Financiero!$F$5:$M$5) -> 758011 | E37: =SUMPRODUCT((Financiero!$F$4:$M$4<Parametros!$C$6)*Financiero!$F$7:$M$7)+SUMPRODUCT((Financiero!$F$4:$M$4=Parametros!$C$6)*Financiero!$F$6:$M$6) -> 224656.16 | F37: =SUMPRODUCT((Financiero!$F$4:$M$4<=Parametros!$C$6)*Financiero!$F$7:$M$7)+N(Escenarios!D16) -> 224656.16 | G37: =SUMPRODUCT((Fisico!$F$4:$M$4<=Parametros!$C$6)*Fisico!$F$5:$M$5) -> 1 | H37: =SUMPRODUCT((Fisico!$F$4:$M$4<Parametros!$C$6)*Fisico!$F$7:$M$7)+SUMPRODUCT((Fisico!$F$4:$M$4=Parametros!$C$6)*Fisico!$F$6:$M$6) -> 0 | I37: =SUMPRODUCT((Fisico!$F$4:$M$4<=Parametros!$C$6)*Fisico!$F$7:$M$7)+N(Escenarios!C16) -> 0 | J37: =IF(G37=0,"N/A",I37/G37) -> 0 | K37: =IF(H37=0,"N/A",I37/H37) -> N/A | L37: =IF(C37="Sí",SUMIF($A$57:$A$61,A37,$H$57:$H$61),IF(J37="N/A",F37,J37*D37)) -> 0 | M37: =IF(C37="Sí",SUMIF($A$57:$A$61,A37,$I$57:$I$61),IF(K37="N/A",F37,K37*E37)) -> 224656.16
A38: 2 | B38: =Fisico!B8 -> P1.2. Sistema de información delictual fortalecidos y en funcionamiento | C38: =Fisico!D8 -> No | D38: =SUMPRODUCT((Financiero!$F$4:$M$4<=Parametros!$C$6)*Financiero!$F$8:$M$8) -> 3104457 | E38: =SUMPRODUCT((Financiero!$F$4:$M$4<Parametros!$C$6)*Financiero!$F$10:$M$10)+SUMPRODUCT((Financiero!$F$4:$M$4=Parametros!$C$6)*Financiero!$F$9:$M$9) -> 23360 | F38: =SUMPRODUCT((Financiero!$F$4:$M$4<=Parametros!$C$6)*Financiero!$F$10:$M$10)+N(Escenarios!D17) -> 23360 | G38: =SUMPRODUCT((Fisico!$F$4:$M$4<=Parametros!$C$6)*Fisico!$F$8:$M$8) -> 1 | H38: =SUMPRODUCT((Fisico!$F$4:$M$4<Parametros!$C$6)*Fisico!$F$10:$M$10)+SUMPRODUCT((Fisico!$F$4:$M$4=Parametros!$C$6)*Fisico!$F$9:$M$9) -> 0 | I38: =SUMPRODUCT((Fisico!$F$4:$M$4<=Parametros!$C$6)*Fisico!$F$10:$M$10)+N(Escenarios!C17) -> 0 | J38: =IF(G38=0,"N/A",I38/G38) -> 0 | K38: =IF(H38=0,"N/A",I38/H38) -> N/A | L38: =IF(C38="Sí",SUMIF($A$57:$A$61,A38,$H$57:$H$61),IF(J38="N/A",F38,J38*D38)) -> 0 | M38: =IF(C38="Sí",SUMIF($A$57:$A$61,A38,$I$57:$I$61),IF(K38="N/A",F38,K38*E38)) -> 23360
A39: 3 | B39: =Fisico!B11 -> P.1.3. Departamentos de la FP capacitados en análisis criminal y monitoreo de dinámicas delictivas | C39: =Fisico!D11 -> No | D39: =SUMPRODUCT((Financiero!$F$4:$M$4<=Parametros!$C$6)*Financiero!$F$11:$M$11) -> 300000 | E39: =SUMPRODUCT((Financiero!$F$4:$M$4<Parametros!$C$6)*Financiero!$F$13:$M$13)+SUMPRODUCT((Financiero!$F$4:$M$4=Parametros!$C$6)*Financiero!$F$12:$M$12) -> 140489.6 | F39: =SUMPRODUCT((Financiero!$F$4:$M$4<=Parametros!$C$6)*Financiero!$F$13:$M$13)+N(Escenarios!D18) -> 140489.6 | G39: =SUMPRODUCT((Fisico!$F$4:$M$4<=Parametros!$C$6)*Fisico!$F$11:$M$11) -> 16 | H39: =SUMPRODUCT((Fisico!$F$4:$M$4<Parametros!$C$6)*Fisico!$F$13:$M$13)+SUMPRODUCT((Fisico!$F$4:$M$4=Parametros!$C$6)*Fisico!$F$12:$M$12) -> 29 | I39: =SUMPRODUCT((Fisico!$F$4:$M$4<=Parametros!$C$6)*Fisico!$F$13:$M$13)+N(Escenarios!C18) -> 29 | J39: =IF(G39=0,"N/A",I39/G39) -> 1.8125 | K39: =IF(H39=0,"N/A",I39/H39) -> 1 | L39: =IF(C39="Sí",SUMIF($A$57:$A$61,A39,$H$57:$H$61),IF(J39="N/A",F39,J39*D39)) -> 543750 | M39: =IF(C39="Sí",SUMIF($A$57:$A$61,A39,$I$57:$I$61),IF(K39="N/A",F39,K39*E39)) -> 140489.6
A40: 4 | B40: =Fisico!B14 -> P.1.4. Estrategias policiales basadas en evidencia diseñadas e implementadas | C40: =Fisico!D14 -> No | D40: =SUMPRODUCT((Financiero!$F$4:$M$4<=Parametros!$C$6)*Financiero!$F$14:$M$14) -> 1603001 | E40: =SUMPRODUCT((Financiero!$F$4:$M$4<Parametros!$C$6)*Financiero!$F$16:$M$16)+SUMPRODUCT((Financiero!$F$4:$M$4=Parametros!$C$6)*Financiero!$F$15:$M$15) -> 1399764.2 | F40: =SUMPRODUCT((Financiero!$F$4:$M$4<=Parametros!$C$6)*Financiero!$F$16:$M$16)+N(Escenarios!D19) -> 835473.63 | G40: =SUMPRODUCT((Fisico!$F$4:$M$4<=Parametros!$C$6)*Fisico!$F$14:$M$14) -> 1 | H40: =SUMPRODUCT((Fisico!$F$4:$M$4<Parametros!$C$6)*Fisico!$F$16:$M$16)+SUMPRODUCT((Fisico!$F$4:$M$4=Parametros!$C$6)*Fisico!$F$15:$M$15) -> 1 | I40: =SUMPRODUCT((Fisico!$F$4:$M$4<=Parametros!$C$6)*Fisico!$F$16:$M$16)+N(Escenarios!C19) -> 0 | J40: =IF(G40=0,"N/A",I40/G40) -> 0 | K40: =IF(H40=0,"N/A",I40/H40) -> 0 | L40: =IF(C40="Sí",SUMIF($A$57:$A$61,A40,$H$57:$H$61),IF(J40="N/A",F40,J40*D40)) -> 0 | M40: =IF(C40="Sí",SUMIF($A$57:$A$61,A40,$I$57:$I$61),IF(K40="N/A",F40,K40*E40)) -> 0
A41: 5 | B41: =Fisico!B17 -> P.1.5. Evaluación de impacto de estrategias policiales basadas en evidencia diseñada e implementada | C41: =Fisico!D17 -> No | D41: =SUMPRODUCT((Financiero!$F$4:$M$4<=Parametros!$C$6)*Financiero!$F$17:$M$17) -> 150000 | E41: =SUMPRODUCT((Financiero!$F$4:$M$4<Parametros!$C$6)*Financiero!$F$19:$M$19)+SUMPRODUCT((Financiero!$F$4:$M$4=Parametros!$C$6)*Financiero!$F$18:$M$18) -> 130000 | F41: =SUMPRODUCT((Financiero!$F$4:$M$4<=Parametros!$C$6)*Financiero!$F$19:$M$19)+N(Escenarios!D20) -> 97637.5 | G41: =SUMPRODUCT((Fisico!$F$4:$M$4<=Parametros!$C$6)*Fisico!$F$17:$M$17) -> 1 | H41: =SUMPRODUCT((Fisico!$F$4:$M$4<Parametros!$C$6)*Fisico!$F$19:$M$19)+SUMPRODUCT((Fisico!$F$4:$M$4=Parametros!$C$6)*Fisico!$F$18:$M$18) -> 1 | I41: =SUMPRODUCT((Fisico!$F$4:$M$4<=Parametros!$C$6)*Fisico!$F$19:$M$19)+N(Escenarios!C20) -> 0 | J41: =IF(G41=0,"N/A",I41/G41) -> 0 | K41: =IF(H41=0,"N/A",I41/H41) -> 0 | L41: =IF(C41="Sí",SUMIF($A$57:$A$61,A41,$H$57:$H$61),IF(J41="N/A",F41,J41*D41)) -> 0 | M41: =IF(C41="Sí",SUMIF($A$57:$A$61,A41,$I$57:$I$61),IF(K41="N/A",F41,K41*E41)) -> 0
